2016-03-25 09:05:47,981 [ERROR] django.request: Internal Server Error: /
Traceback (most recent call last):
  File "/Library/Python/2.7/site-packages/django/core/handlers/base.py", line 134, in get_response
    resolver_match = resolver.resolve(request.path_info)
  File "/Library/Python/2.7/site-packages/django/core/urlresolvers.py", line 376, in resolve
    sub_match = pattern.resolve(new_path)
  File "/Library/Python/2.7/site-packages/django/core/urlresolvers.py", line 376, in resolve
    sub_match = pattern.resolve(new_path)
  File "/Library/Python/2.7/site-packages/django/core/urlresolvers.py", line 248, in resolve
    return ResolverMatch(self.callback, args, kwargs, self.name)
  File "/Library/Python/2.7/site-packages/django/core/urlresolvers.py", line 255, in callback
    self._callback = get_callable(self._callback_str)
  File "/Library/Python/2.7/site-packages/django/utils/lru_cache.py", line 100, in wrapper
    result = user_function(*args, **kwds)
  File "/Library/Python/2.7/site-packages/django/core/urlresolvers.py", line 115, in get_callable
    mod = import_module(mod_name)
  File "/System/Library/Frameworks/Python.framework/Versions/2.7/lib/python2.7/importlib/__init__.py", line 37, in import_module
    __import__(name)
  File "/Users/manoj/Documents/gmaps/localities/views.py", line 30
    logger.debug("Gemetry: "locality)
                                   ^
SyntaxError: invalid syntax
2016-03-25 09:34:11,616 [ERROR] django.request: Internal Server Error: /
Traceback (most recent call last):
  File "/Library/Python/2.7/site-packages/django/core/handlers/base.py", line 134, in get_response
    resolver_match = resolver.resolve(request.path_info)
  File "/Library/Python/2.7/site-packages/django/core/urlresolvers.py", line 376, in resolve
    sub_match = pattern.resolve(new_path)
  File "/Library/Python/2.7/site-packages/django/core/urlresolvers.py", line 376, in resolve
    sub_match = pattern.resolve(new_path)
  File "/Library/Python/2.7/site-packages/django/core/urlresolvers.py", line 248, in resolve
    return ResolverMatch(self.callback, args, kwargs, self.name)
  File "/Library/Python/2.7/site-packages/django/core/urlresolvers.py", line 255, in callback
    self._callback = get_callable(self._callback_str)
  File "/Library/Python/2.7/site-packages/django/utils/lru_cache.py", line 100, in wrapper
    result = user_function(*args, **kwds)
  File "/Library/Python/2.7/site-packages/django/core/urlresolvers.py", line 115, in get_callable
    mod = import_module(mod_name)
  File "/System/Library/Frameworks/Python.framework/Versions/2.7/lib/python2.7/importlib/__init__.py", line 37, in import_module
    __import__(name)
  File "/Users/manoj/Documents/gmaps/localities/views.py", line 13, in <module>
    @csrf_protect
NameError: name 'csrf_protect' is not defined
2016-03-25 13:57:44,870 [ERROR] django.request: Internal Server Error: /save
Traceback (most recent call last):
  File "/Library/Python/2.7/site-packages/django/core/handlers/base.py", line 149, in get_response
    response = self.process_exception_by_middleware(e, request)
  File "/Library/Python/2.7/site-packages/django/core/handlers/base.py", line 147, in get_response
    response = wrapped_callback(request, *callback_args, **callback_kwargs)
  File "/Library/Python/2.7/site-packages/django/utils/decorators.py", line 149, in _wrapped_view
    response = view_func(request, *args, **kwargs)
  File "/Users/manoj/Documents/gmaps/localities/views.py", line 33, in save
    return HttpResponse(simplejson.dumps(dict(isOk=1)), mimetype='application/json')
  File "/Library/Python/2.7/site-packages/django/http/response.py", line 283, in __init__
    super(HttpResponse, self).__init__(*args, **kwargs)
TypeError: __init__() got an unexpected keyword argument 'mimetype'
